Workbook
Name Slicer_City_tier: #N/A
Name Slicer_Hospital_tier: #N/A
Name Slicer_smoker: #N/A
Name Slicer_Weight_Status: #N/A

Sheet Customer Names
A1: Customer ID | B1: Title | C1: First Name | D1: Last Name
A2: Id1 | B2: Ms | C2: Kelly | D2: Hawks
A3: Id2 | B3: Mr | C3: Matthew D | D3: Lehner
A4: Id3 | B4: Mr | C4: Phil | D4: Lu
A5: Id4 | B5: Ms | C5: Kelsey | D5: Osborne
A6: Id5 | B6: Ms | C6: Kristyn | D6: Kadala
A7: Id6 | B7: Mr | C7: Russell B | D7: Baker
A8: Id7 | B8: Mr | C8: Scott | D8: Macpherson
A9: Id8 | B9: Mr | C9: Stephen | D9: Hallman
A10: Id9 | B10: Mr | C10: Patrick R | D10: Moran
A11: Id10 | B11: Ms | C11: Brooke N | D11: Benner
A12: Id11 | B12: Ms | C12: Paola Andrea | D12: Fierro Vargas
... A2336: Id2335 | B2336: Mr | C2336: Aaron K | D2336: German

Sheet Medical Examinations
A1: Customer ID | B1: BMI | C1: Weight Status | D1: HBA1C | E1: Diabetes Status | F1: Heart Issues | G1: Any Transplants | H1: Cancer history | I1: NumberOfMajorSurgeries | J1: smoker
A2: Id1 | B2: 47.41 | C2: Obesity | D2: 7.47 | E2: Diabetes | F2: No | G2: No | H2: No | I2: 0 | J2: Yes
A3: Id10 | B3: 38.06 | C3: Obesity | D3: 10.79 | E3: Diabetes | F3: No | G3: No | H3: No | I3: 0 | J3: Yes
A4: Id100 | B4: 48.2 | C4: Obesity | D4: 4.84 | E4: Normal | F4: No | G4: No | H4: No | I4: 0 | J4: Yes
A5: Id1000 | B5: 39.17 | C5: Obesity | D5: 4.15 | E5: Normal | F5: No | G5: No | H5: No | I5: 0 | J5: No
A6: Id1001 | B6: 26.41 | C6: Overweight | D6: 5.99 | E6: Prediabetes | F6: Yes | G6: No | H6: Yes | I6: 1 | J6: No
A7: Id1002 | B7: 30.63 | C7: Obesity | D7: 5.8 | E7: Prediabetes | F7: Yes | G7: No | H7: No | I7: 0 | J7: No
A8: Id1003 | B8: 31.73 | C8: Obesity | D8: 7.32 | E8: Diabetes | F8: Yes | G8: No | H8: No | I8: 2 | J8: No
A9: Id1004 | B9: 30.7 | C9: Obesity | D9: 5.16 | E9: Normal | F9: No | G9: No | H9: No | I9: 2 | J9: No
A10: Id1005 | B10: 25.935 | C10: Overweight | D10: 5.96 | E10: Prediabetes | F10: Yes | G10: No | H10: No | I10: 2 | J10: No
A11: Id1006 | B11: 35.9 | C11: Obesity | D11: 4.85 | E11: Normal | F11: Yes | G11: No | H11: Yes | I11: 1 | J11: No
A12: Id1007 | B12: 26.7 | C12: Overweight | D12: 5.09 | E12: Normal | F12: Yes | G12: No | H12: Yes | I12: 1 | J12: No
A13: Id1008 | B13: 33.71 | C13: Obesity | D13: 4.94 | E13: Normal | F13: No | G13: No | H13: No | I13: 0 | J13: No
... A2336: Id999 | B2336: 28.6 | C2336: Overweight | D2336: 5.56 | E2336: Normal | F2336: Yes | G2336: No | H2336: Yes | I2336: 1 | J2336: No

Sheet Hospitalisation Details
A1: Customer ID | B1: year | C1: month | D1: date | E1: Date of Birth | F1: Age | G1: children | H1: charges | I1: Hospital tier | J1: City tier | K1: State ID
A2: Id1 | B2: 1968 | C2: Oct | D2: 12 | E2: 25123 | F2: 54 | G2: 0 | H2: 63770.43 | I2: tier - 1 | J2: tier - 3 | K2: R1013
A3: Id10 | B3: 1978 | C3: Dec | D3: 29 | E3: 28853 | F3: 44 | G3: 0 | H3: 48885.14 | I3: tier - 1 | J3: tier - 2 | K3: R1013
A4: Id100 | B4: 1977 | C4: Jun | D4: 27 | E4: 28303 | F4: 45 | G4: 2 | H4: 40284.38 | I4: tier - 1 | J4: tier - 3 | K4: R1012
A5: Id1000 | B5: 1989 | C5: Dec | D5: 17 | E5: 32859 | F5: 33 | G5: 3 | H5: 11250.43 | I5: tier - 3 | J5: tier - 2 | K5: R1026
A6: Id1001 | B6: 1969 | C6: Dec | D6: 30 | E6: 25567 | F6: 53 | G6: 2 | H6: 11244.38 | I6: tier - 3 | J6: tier - 1 | K6: R1016
A7: Id1002 | B7: 1976 | C7: Jun | D7: 28 | E7: 27939 | F7: 46 | G7: 2 | H7: 11217.35 | I7: tier - 3 | J7: tier - 2 | K7: R1025
A8: Id1003 | B8: 1970 | C8: Jun | D8: 14 | E8: 25733 | F8: 52 | G8: 2 | H8: 11187.66 | I8: tier - 3 | J8: tier - 2 | K8: R1012
A9: Id1004 | B9: 1972 | C9: Sep | D9: 3 | E9: 26545 | F9: 50 | G9: 0 | H9: 11186.2 | I9: tier - 3 | J9: tier - 2 | K9: R1021
A10: Id1005 | B10: 1966 | C10: Aug | D10: 6 | E10: 24325 | F10: 56 | G10: 0 | H10: 11165.42 | I10: tier - 3 | J10: tier - 1 | K10: R1016
A11: Id1006 | B11: 1969 | C11: Jun | D11: 25 | E11: 25379 | F11: 53 | G11: 2 | H11: 11163.57 | I11: tier - 3 | J11: tier - 2 | K11: R1011
A12: Id1007 | B12: 1969 | C12: Nov | D12: 30 | E12: 25537 | F12: 53 | G12: 2 | H12: 11150.78 | I12: tier - 3 | J12: tier - 2 | K12: R1011
A13: Id1008 | B13: 1980 | C13: Aug | D13: 20 | E13: 29453 | F13: 42 | G13: 2 | H13: 11103.33 | I13: tier - 3 | J13: tier - 1 | K13: R1021
... A2344: Id2343 | B2344: 1969 | C2344: Aug | D2344: 20 | E2344: 25435 | F2344: 53 | G2344: 3 | H2344: 11253.42 | I2344: tier - 3 | J2344: tier - 1 | K2344: R1011

Sheet Data Cleaning Q1 to Q4
A1: Customer ID | B1: BMI | C1: HBA1C | D1: Heart Issues | E1: Any Transplants | F1: Cancer history | G1: NumberOfMajorSurgeries | H1: smoker | J1: Customer ID | K1: year | L1: month | M1: date | N1: children | O1: charges | P1: Hospital tier | Q1: City tier | R1: State ID | T1: 1) Check for the number of missing values marked with 'No' in each column of the “Medical Examinations” Table and "Hospitalization Details" Table.
A2: Id1 | B2: 47.41 | C2: 7.47 | D2: No | E2: No | F2: No | G2: No major surgery | H2: yes | J2: Id1 | K2: 1968 | L2: Oct | M2: 12 | N2: 0 | O2: 63770.43 | P2: tier - 1 | Q2: tier - 3 | R2: R1013
A3: Id10 | B3: 38.06 | C3: 10.79 | D3: No | E3: No | F3: No | G3: No major surgery | H3: yes | J3: Id10 | K3: 1978 | L3: Dec | M3: 29 | N3: 0 | O3: 48885.14 | P3: tier - 1 | Q3: tier - 2 | R3: R1013 | T3: Missing Values Appears To Be Medical Examinations | U3: =COUNTIF(A2:H2336,"?") -> 0 | V3: Before Cleaning - 2
A4: Id100 | B4: 48.2 | C4: 4.84 | D4: No | E4: No | F4: No | G4: No major surgery | H4: yes | J4: Id100 | K4: 1977 | L4: Jun | M4: 27 | N4: 2 | O4: 40284.38 | P4: tier - 1 | Q4: tier - 3 | R4: R1012 | T4: Missing Values Appears To Be Hospitalisation Details | U4: =COUNTIF(J2:R2344,"?") -> 0 | V4: Before Cleaning - 15
A5: Id1000 | B5: 39.17 | C5: 4.15 | D5: No | E5: No | F5: No | G5: No major surgery | H5: No | J5: Id1000 | K5: 1989 | L5: Dec | M5: 17 | N5: 3 | O5: 11250.43 | P5: tier - 3 | Q5: tier - 2 | R5: R1026
A6: Id1001 | B6: 26.41 | C6: 5.99 | D6: yes | E6: No | F6: Yes | G6: 1 | H6: No | J6: Id1001 | K6: 1969 | L6: Dec | M6: 30 | N6: 2 | O6: 11244.38 | P6: tier - 3 | Q6: tier - 1 | R6: R1016
A7: Id1002 | B7: 30.63 | C7: 5.8 | D7: yes | E7: No | F7: No | G7: No major surgery | H7: No | J7: Id1002 | K7: 1976 | L7: Jun | M7: 28 | N7: 2 | O7: 11217.35 | P7: tier - 3 | Q7: tier - 2 | R7: R1025 | T7: 2) Fill in the missing values of ‘month’ with Sep and ‘year’ with its average rounded to the nearest integer.
A8: Id1003 | B8: 31.73 | C8: 7.32 | D8: yes | E8: No | F8: No | G8: 2 | H8: No | J8: Id1003 | K8: 1970 | L8: Jun | M8: 14 | N8: 2 | O8: 11187.66 | P8: tier - 3 | Q8: tier - 2 | R8: R1012 | T8: average year | U8: =ROUND(AVERAGE(K2:K2344),0) -> 1983
A9: Id1004 | B9: 30.7 | C9: 5.16 | D9: No | E9: No | F9: No | G9: 2 | H9: No | J9: Id1004 | K9: 1972 | L9: Sep | M9: 3 | N9: 0 | O9: 11186.2 | P9: tier - 3 | Q9: tier - 2 | R9: R1021
A10: Id1005 | B10: 25.935 | C10: 5.96 | D10: yes | E10: No | F10: No | G10: 2 | H10: No | J10: Id1005 | K10: 1966 | L10: Aug | M10: 6 | N10: 0 | O10: 11165.42 | P10: tier - 3 | Q10: tier - 1 | R10: R1016 | T10: 3) Determine the most frequently occurring values in the ‘smoker’, 'Hospital tier' and 'City tier' columns, and fill in the missing values accordingly.
A11: Id1006 | B11: 35.9 | C11: 4.85 | D11: yes | E11: No | F11: Yes | G11: 1 | H11: No | J11: Id1006 | K11: 1969 | L11: Jun | M11: 25 | N11: 2 | O11: 11163.57 | P11: tier - 3 | Q11: tier - 2 | R11: R1011 | T11: "No" is the Most Frequent value in smoker column
A12: Id1007 | B12: 26.7 | C12: 5.09 | D12: yes | E12: No | F12: Yes | G12: 1 | H12: No | J12: Id1007 | K12: 1969 | L12: Nov | M12: 30 | N12: 2 | O12: 11150.78 | P12: tier - 3 | Q12: tier - 2 | R12: R1011 | V12: No | W12: Yes | X12: Grand Total
A13: Id1008 | B13: 33.71 | C13: 4.94 | D13: No | E13: No | F13: No | G13: No major surgery | H13: No | J13: Id1008 | K13: 1980 | L13: Aug | M13: 20 | N13: 2 | O13: 11103.33 | P13: tier - 3 | Q13: tier - 1 | R13: R1021 | U13: Count of smoker | V13: 1847 | W13: 488 | X13: 2335
A14: Id1009 | B14: 41.91 | C14: 4.92 | D14: yes | E14: No | F14: No | G14: 2 | H14: No | J14: Id1009 | K14: 1966 | L14: Jul | M14: 5 | N14: 0 | O14: 11093.62 | P14: tier - 3 | Q14: tier - 1 | R14: R1013
A15: Id101 | B15: 35.75 | C15: 8 | D15: yes | E15: No | F15: No | G15: No major surgery | H15: yes | J15: Id101 | K15: 1981 | L15: Oct | M15: 4 | N15: 1 | O15: 40273.65 | P15: tier - 1 | Q15: tier - 3 | R15: R1013
A16: Id1010 | B16: 39.82 | C16: 6.05 | D16: yes | E16: No | F16: No | G16: 2 | H16: No | J16: Id1010 | K16: 1966 | L16: Sep | M16: 9 | N16: 0 | O16: 11090.72 | P16: tier - 3 | Q16: tier - 1 | R16: R1013 | T16: most frequently occurring values 'Hospital tier' | U16: Hospital tier | V16: Count of Hospital tier
A17: Id1011 | B17: 28.12 | C17: 4.67 | D17: No | E17: No | F17: No | G17: 2 | H17: No | J17: Id1011 | K17: 1972 | L17: Oct | M17: 7 | N17: 3 | O17: 11085.59 | P17: tier - 3 | Q17: tier - 2 | R17: R1012 | U17: tier - 1 | V17: 309
A18: Id1012 | B18: 26.98 | C18: 9.81 | D18: yes | E18: No | F18: No | G18: No major surgery | H18: No | J18: Id1012 | K18: 1967 | L18: Sep | M18: 4 | N18: 0 | O18: 11082.58 | P18: tier - 3 | Q18: tier - 2 | R18: R1012 | U18: tier - 2 | V18: 1340
A19: Id1013 | B19: 27.2 | C19: 6.06 | D19: yes | E19: No | F19: No | G19: 2 | H19: No | J19: Id1013 | K19: 1966 | L19: Nov | M19: 20 | N19: 0 | O19: 11073.18 | P19: tier - 3 | Q19: tier - 3 | R19: R1011 | U19: tier - 3 | V19: 694
A20: Id1014 | B20: 25.3 | C20: 5.19 | D20: yes | E20: No | F20: No | G20: 2 | H20: No | J20: Id1014 | K20: 1966 | L20: Nov | M20: 7 | N20: 0 | O20: 11070.54 | P20: tier - 3 | Q20: tier - 3 | R20: R1011 | U20: Grand Total | V20: 2343
A21: Id1015 | B21: 30.25 | C21: 10.16 | D21: No | E21: No | F21: No | G21: No major surgery | H21: No | J21: Id1015 | K21: 1971 | L21: Nov | M21: 9 | N21: 0 | O21: 11068.77 | P21: tier - 3 | Q21: tier - 2 | R21: R1012
A22: Id1016 | B22: 54 | C22: 4.68 | D22: yes | E22: yes | F22: No | G22: 2 | H22: No | J22: Id1016 | K22: 2000 | L22: Sep | M22: 18 | N22: 0 | O22: 11068.7 | P22: tier - 3 | Q22: tier - 1 | R22: R1011
A23: Id1017 | B23: 51.86 | C23: 5.32 | D23: yes | E23: No | F23: No | G23: No major surgery | H23: No | J23: Id1017 | K23: 2001 | L23: Dec | M23: 17 | N23: 0 | O23: 11046.02 | P23: tier - 3 | Q23: tier - 1 | R23: R1026 | T23: most frequently occurring values 'City tier' | U23: City Labels | V23: Count of City tier
A24: Id1018 | B24: 31.39 | C24: 6.99 | D24: No | E24: No | F24: No | G24: No major surgery | H24: No | J24: Id1018 | K24: 1974 | L24: Aug | M24: 30 | N24: 0 | O24: 11037.85 | P24: tier - 3 | Q24: tier - 2 | R24: R1025 | U24: tier - 1 | V24: 734
A25: Id1019 | B25: 39.97 | C25: 5.55 | D25: No | E25: No | F25: No | G25: No major surgery | H25: No | J25: Id1019 | K25: 1989 | L25: Oct | M25: 25 | N25: 3 | O25: 11037.51 | P25: tier - 3 | Q25: tier - 1 | R25: R1012 | U25: tier - 2 | V25: 813
A26: Id102 | B26: 53.81 | C26: 8.77 | D26: yes | E26: No | F26: No | G26: No major surgery | H26: yes | J26: Id102 | K26: 1981 | L26: Jul | M26: 28 | N26: 1 | O26: 40208.56 | P26: tier - 1 | Q26: tier - 2 | R26: R1011 | U26: tier - 3 | V26: 796
A27: Id1020 | B27: 41.23 | C27: 6.94 | D27: No | E27: No | F27: No | G27: No major surgery | H27: No | J27: Id1020 | K27: 1974 | L27: Dec | M27: 10 | N27: 4 | O27: 11033.66 | P27: tier - 3 | Q27: tier - 3 | R27: R1012 | U27: Grand Total | V27: 2343
A28: Id1021 | B28: 49.45 | C28: 4.2 | D28: yes | E28: No | F28: No | G28: No major surgery | H28: No | J28: Id1021 | K28: 1996 | L28: Jul | M28: 21 | N28: 0 | O28: 11028.56 | P28: tier - 3 | Q28: tier - 3 | R28: R1012
A29: Id1022 | B29: 41.04 | C29: 5.59 | D29: No | E29: No | F29: No | G29: No major surgery | H29: No | J29: Id1022 | K29: 1991 | L29: Jun | M29: 26 | N29: 3 | O29: 11018.05 | P29: tier - 3 | Q29: tier - 2 | R29: R1012
A30: Id1023 | B30: 27.93 | C30: 9.96 | D30: No | E30: No | F30: No | G30: No major surgery | H30: No | J30: Id1023 | K30: 1974 | L30: Dec | M30: 15 | N30: 4 | O30: 11015.17 | P30: tier - 3 | Q30: tier - 1 | R30: R1012 | T30: 4) If any 'State ID' values are missing, consider filling them with 'Unknown' or using another appropriate strategy.
A31: Id1024 | B31: 21.01 | C31: 7.37 | D31: No | E31: No | F31: No | G31: No major surgery | H31: No | J31: Id1024 | K31: 1968 | L31: Oct | M31: 24 | N31: 2 | O31: 11013.71 | P31: tier - 3 | Q31: tier - 1 | R31: R1013
A32: Id1025 | B32: 52.37 | C32: 5.06 | D32: yes | E32: yes | F32: No | G32: 2 | H32: No | J32: Id1025 | K32: 2000 | L32: Sep | M32: 17 | N32: 0 | O32: 10991.58 | P32: tier - 3 | Q32: tier - 3 | R32: R1012
A33: Id1026 | B33: 40.37 | C33: 8.21 | D33: No | E33: No | F33: No | G33: No major surgery | H33: No | J33: Id1026 | K33: 1965 | L33: Dec | M33: 18 | N33: 0 | O33: 10982.5 | P33: tier - 3 | Q33: tier - 3 | R33: R1013
A34: Id1027 | B34: 41.47 | C34: 10.34 | D34: No | E34: No | F34: No | G34: 2 | H34: No | J34: Id1027 | K34: 1973 | L34: Oct | M34: 21 | N34: 4 | O34: 10977.21 | P34: tier - 3 | Q34: tier - 1 | R34: R1013
A35: Id1028 | B35: 33.725 | C35: 5.51 | D35: yes | E35: No | F35: No | G35: 2 | H35: No | J35: Id1028 | K35: 1966 | L35: Jul | M35: 9 | N35: 0 | O35: 10976.25 | P35: tier - 3 | Q35: tier - 2 | R35: R1012
A36: Id1029 | B36: 28.1 | C36: 11.2 | D36: No | E36: No | F36: No | G36: No major surgery | H36: No | J36: Id1029 | K36: 1965 | L36: Jun | M36: 19 | N36: 0 | O36: 10965.45 | P36: tier - 3 | Q36: tier - 2 | R36: R1011
A37: Id103 | B37: 49.48 | C37: 4.96 | D37: No | E37: No | F37: Yes | G37: 1 | H37: yes | J37: Id103 | K37: 1979 | L37: Aug | M37: 18 | N37: 2 | O37: 40204.83 | P37: tier - 1 | Q37: tier - 3 | R37: R1012
A38: Id1030 | B38: 37.43 | C38: 4.35 | D38: yes | E38: No | F38: Yes | G38: 1 | H38: No | J38: Id1030 | K38: 1969 | L38: Aug | M38: 14 | N38: 1 | O38: 10959.69 | P38: tier - 3 | Q38: tier - 3 | R38: R1012
A39: Id1031 | B39: 23.7 | C39: 10.45 | D39: No | E39: No | F39: No | G39: No major surgery | H39: No | J39: Id1031 | K39: 1965 | L39: Dec | M39: 4 | N39: 0 | O39: 10959.33 | P39: tier - 3 | Q39: tier - 3 | R39: R1011
A40: Id1032 | B40: 24.795 | C40: 4.07 | D40: yes | E40: No | F40: Yes | G40: 1 | H40: No | J40: Id1032 | K40: 1969 | L40: Nov | M40: 10 | N40: 1 | O40: 10942.13 | P40: tier - 3 | Q40: tier - 3 | R40: R1012
...

Sheet Data Transformation Q1 to Q8
A1: Customer ID | B1: BMI | C1: Weight Status | D1: HBA1C | E1: Diabetes Status | F1: Heart Issues | G1: Any Transplants | H1: Cancer history | I1: NumberOfMajorSurgeries | J1: smoker | L1: Customer ID | M1: year | N1: month | O1: date | P1: Date of Birth | Q1: Age | R1: children | S1: charges | T1: Hospital tier | U1: City tier | V1: State ID
A2: Id1 | B2: 47.41 | C2: {=_xlfn.IFS($B2<18.5,"Underweight",$B2<24.9,"Normal Weight",$B2<29.9,"Overweight",TRUE,"Obesity")} -> Obesity | D2: 7.47 | E2: =IF($D2<5.7,"Normal",IF($D2<6.5,"Prediabetes","Diabetes")) -> Diabetes | F2: No | G2: No | H2: No | I2: 0 | J2: Yes | L2: Id1 | M2: 1968 | N2: Oct | O2: 12 | P2: =DATE($M2,MONTH(1&$N2),$O2) -> 25123 | Q2: =DATEDIF($P2,DATE(2023,6,8),"Y") -> 54 | R2: 0 | S2: 63770.43 | T2: tier - 1 | U2: tier - 3 | V2: R1013 | X2: 1) Split the ‘names’ column in the “Customer Names” Table into 3 meaningful columns: ‘Title’, ‘First Name’, and ‘Last Name’.
A3: Id10 | B3: 38.06 | C3: {=_xlfn.IFS($B3<18.5,"Underweight",$B3<24.9,"Normal Weight",$B3<29.9,"Overweight",TRUE,"Obesity")} -> Obesity | D3: 10.79 | E3: =IF($D3<5.7,"Normal",IF($D3<6.5,"Prediabetes","Diabetes")) -> Diabetes | F3: No | G3: No | H3: No | I3: 0 | J3: Yes | L3: Id10 | M3: 1978 | N3: Dec | O3: 29 | P3: =DATE($M3,MONTH(1&$N3),$O3) -> 28853 | Q3: =DATEDIF($P3,DATE(2023,6,8),"Y") -> 44 | R3: 0 | S3: 48885.14 | T3: tier - 1 | U3: tier - 2 | V3: R1013 | X3: Check at "Customer Names" Sheet
A4: Id100 | B4: 48.2 | C4: {=_xlfn.IFS($B4<18.5,"Underweight",$B4<24.9,"Normal Weight",$B4<29.9,"Overweight",TRUE,"Obesity")} -> Obesity | D4: 4.84 | E4: =IF($D4<5.7,"Normal",IF($D4<6.5,"Prediabetes","Diabetes")) -> Normal | F4: No | G4: No | H4: No | I4: 0 | J4: Yes | L4: Id100 | M4: 1977 | N4: Jun | O4: 27 | P4: =DATE($M4,MONTH(1&$N4),$O4) -> 28303 | Q4: =DATEDIF($P4,DATE(2023,6,8),"Y") -> 45 | R4: 2 | S4: 40284.38 | T4: tier - 1 | U4: tier - 3 | V4: R1012
A5: Id1000 | B5: 39.17 | C5: {=_xlfn.IFS($B5<18.5,"Underweight",$B5<24.9,"Normal Weight",$B5<29.9,"Overweight",TRUE,"Obesity")} -> Obesity | D5: 4.15 | E5: =IF($D5<5.7,"Normal",IF($D5<6.5,"Prediabetes","Diabetes")) -> Normal | F5: No | G5: No | H5: No | I5: 0 | J5: No | L5: Id1000 | M5: 1989 | N5: Dec | O5: 17 | P5: =DATE($M5,MONTH(1&$N5),$O5) -> 32859 | Q5: =DATEDIF($P5,DATE(2023,6,8),"Y") -> 33 | R5: 3 | S5: 11250.43 | T5: tier - 3 | U5: tier - 2 | V5: R1026 | X5: 2) Convert the "NumberOfMajorSurgeries" column in the “Medical Examinations” Table to numerical data by replacing non-numeric characters with meaningful numerical values.
A6: Id1001 | B6: 26.41 | C6: {=_xlfn.IFS($B6<18.5,"Underweight",$B6<24.9,"Normal Weight",$B6<29.9,"Overweight",TRUE,"Obesity")} -> Overweight | D6: 5.99 | E6: =IF($D6<5.7,"Normal",IF($D6<6.5,"Prediabetes","Diabetes")) -> Prediabetes | F6: Yes | G6: No | H6: Yes | I6: 1 | J6: No | L6: Id1001 | M6: 1969 | N6: Dec | O6: 30 | P6: =DATE($M6,MONTH(1&$N6),$O6) -> 25567 | Q6: =DATEDIF($P6,DATE(2023,6,8),"Y") -> 53 | R6: 2 | S6: 11244.38 | T6: tier - 3 | U6: tier - 1 | V6: R1016 | X6: Original Value | Y6: Converted Value
A7: Id1002 | B7: 30.63 | C7: {=_xlfn.IFS($B7<18.5,"Underweight",$B7<24.9,"Normal Weight",$B7<29.9,"Overweight",TRUE,"Obesity")} -> Obesity | D7: 5.8 | E7: =IF($D7<5.7,"Normal",IF($D7<6.5,"Prediabetes","Diabetes")) -> Prediabetes | F7: Yes | G7: No | H7: No | I7: 0 | J7: No | L7: Id1002 | M7: 1976 | N7: Jun | O7: 28 | P7: =DATE($M7,MONTH(1&$N7),$O7) -> 27939 | Q7: =DATEDIF($P7,DATE(2023,6,8),"Y") -> 46 | R7: 2 | S7: 11217.35 | T7: tier - 3 | U7: tier - 2 | V7: R1025 | X7: No Major Surgery | Y7: 0
A8: Id1003 | B8: 31.73 | C8: {=_xlfn.IFS($B8<18.5,"Underweight",$B8<24.9,"Normal Weight",$B8<29.9,"Overweight",TRUE,"Obesity")} -> Obesity | D8: 7.32 | E8: =IF($D8<5.7,"Normal",IF($D8<6.5,"Prediabetes","Diabetes")) -> Diabetes | F8: Yes | G8: No | H8: No | I8: 2 | J8: No | L8: Id1003 | M8: 1970 | N8: Jun | O8: 14 | P8: =DATE($M8,MONTH(1&$N8),$O8) -> 25733 | Q8: =DATEDIF($P8,DATE(2023,6,8),"Y") -> 52 | R8: 2 | S8: 11187.66 | T8: tier - 3 | U8: tier - 2 | V8: R1012 | X8: 1 | Y8: 1
A9: Id1004 | B9: 30.7 | C9: {=_xlfn.IFS($B9<18.5,"Underweight",$B9<24.9,"Normal Weight",$B9<29.9,"Overweight",TRUE,"Obesity")} -> Obesity | D9: 5.16 | E9: =IF($D9<5.7,"Normal",IF($D9<6.5,"Prediabetes","Diabetes")) -> Normal | F9: No | G9: No | H9: No | I9: 2 | J9: No | L9: Id1004 | M9: 1972 | N9: Sep | O9: 3 | P9: =DATE($M9,MONTH(1&$N9),$O9) -> 26545 | Q9: =DATEDIF($P9,DATE(2023,6,8),"Y") -> 50 | R9: 0 | S9: 11186.2 | T9: tier - 3 | U9: tier - 2 | V9: R1021 | X9: 2 | Y9: 2
A10: Id1005 | B10: 25.935 | C10: {=_xlfn.IFS($B10<18.5,"Underweight",$B10<24.9,"Normal Weight",$B10<29.9,"Overweight",TRUE,"Obesity")} -> Overweight | D10: 5.96 | E10: =IF($D10<5.7,"Normal",IF($D10<6.5,"Prediabetes","Diabetes")) -> Prediabetes | F10: Yes | G10: No | H10: No | I10: 2 | J10: No | L10: Id1005 | M10: 1966 | N10: Aug | O10: 6 | P10: =DATE($M10,MONTH(1&$N10),$O10) -> 24325 | Q10: =DATEDIF($P10,DATE(2023,6,8),"Y") -> 56 | R10: 0 | S10: 11165.42 | T10: tier - 3 | U10: tier - 1 | V10: R1016 | X10: 3 | Y10: 3
A11: Id1006 | B11: 35.9 | C11: {=_xlfn.IFS($B11<18.5,"Underweight",$B11<24.9,"Normal Weight",$B11<29.9,"Overweight",TRUE,"Obesity")} -> Obesity | D11: 4.85 | E11: =IF($D11<5.7,"Normal",IF($D11<6.5,"Prediabetes","Diabetes")) -> Normal | F11: Yes | G11: No | H11: Yes | I11: 1 | J11: No | L11: Id1006 | M11: 1969 | N11: Jun | O11: 25 | P11: =DATE($M11,MONTH(1&$N11),$O11) -> 25379 | Q11: =DATEDIF($P11,DATE(2023,6,8),"Y") -> 53 | R11: 2 | S11: 11163.57 | T11: tier - 3 | U11: tier - 2 | V11: R1011
A12: Id1007 | B12: 26.7 | C12: {=_xlfn.IFS($B12<18.5,"Underweight",$B12<24.9,"Normal Weight",$B12<29.9,"Overweight",TRUE,"Obesity")} -> Overweight | D12: 5.09 | E12: =IF($D12<5.7,"Normal",IF($D12<6.5,"Prediabetes","Diabetes")) -> Normal | F12: Yes | G12: No | H12: Yes | I12: 1 | J12: No | L12: Id1007 | M12: 1969 | N12: Nov | O12: 30 | P12: =DATE($M12,MONTH(1&$N12),$O12) -> 25537 | Q12: =DATEDIF($P12,DATE(2023,6,8),"Y") -> 53 | R12: 2 | S12: 11150.78 | T12: tier - 3 | U12: tier - 2 | V12: R1011 | X12: 3) Check for inconsistencies in the 'Heart Issues' and 'smoker' columns and propose corrective actions if necessary.
A13: Id1008 | B13: 33.71 | C13: {=_xlfn.IFS($B13<18.5,"Underweight",$B13<24.9,"Normal Weight",$B13<29.9,"Overweight",TRUE,"Obesity")} -> Obesity | D13: 4.94 | E13: =IF($D13<5.7,"Normal",IF($D13<6.5,"Prediabetes","Diabetes")) -> Normal | F13: No | G13: No | H13: No | I13: 0 | J13: No | L13: Id1008 | M13: 1980 | N13: Aug | O13: 20 | P13: =DATE($M13,MONTH(1&$N13),$O13) -> 29453 | Q13: =DATEDIF($P13,DATE(2023,6,8),"Y") -> 42 | R13: 2 | S13: 11103.33 | T13: tier - 3 | U13: tier - 1 | V13: R1021 | X13: {=_xlfn.UNIQUE(F2:F2336)} -> No | Y13: {=_xlfn.UNIQUE(J2:J2336)} -> Yes
A14: Id1009 | B14: 41.91 | C14: {=_xlfn.IFS($B14<18.5,"Underweight",$B14<24.9,"Normal Weight",$B14<29.9,"Overweight",TRUE,"Obesity")} -> Obesity | D14: 4.92 | E14: =IF($D14<5.7,"Normal",IF($D14<6.5,"Prediabetes","Diabetes")) -> Normal | F14: Yes | G14: No | H14: No | I14: 2 | J14: No | L14: Id1009 | M14: 1966 | N14: Jul | O14: 5 | P14: =DATE($M14,MONTH(1&$N14),$O14) -> 24293 | Q14: =DATEDIF($P14,DATE(2023,6,8),"Y") -> 56 | R14: 0 | S14: 11093.62 | T14: tier - 3 | U14: tier - 1 | V14: R1013 | X14: Yes | Y14: No
A15: Id101 | B15: 35.75 | C15: {=_xlfn.IFS($B15<18.5,"Underweight",$B15<24.9,"Normal Weight",$B15<29.9,"Overweight",TRUE,"Obesity")} -> Obesity | D15: 8 | E15: =IF($D15<5.7,"Normal",IF($D15<6.5,"Prediabetes","Diabetes")) -> Diabetes | F15: Yes | G15: No | H15: No | I15: 0 | J15: Yes | L15: Id101 | M15: 1981 | N15: Oct | O15: 4 | P15: =DATE($M15,MONTH(1&$N15),$O15) -> 29863 | Q15: =DATEDIF($P15,DATE(2023,6,8),"Y") -> 41 | R15: 1 | S15: 40273.65 | T15: tier - 1 | U15: tier - 3 | V15: R1013 | X15: Ckecked with formula "Uniqe" & Not find any unique Values
A16: Id1010 | B16: 39.82 | C16: {=_xlfn.IFS($B16<18.5,"Underweight",$B16<24.9,"Normal Weight",$B16<29.9,"Overweight",TRUE,"Obesity")} -> Obesity | D16: 6.05 | E16: =IF($D16<5.7,"Normal",IF($D16<6.5,"Prediabetes","Diabetes")) -> Prediabetes | F16: Yes | G16: No | H16: No | I16: 2 | J16: No | L16: Id1010 | M16: 1966 | N16: Sep | O16: 9 | P16: =DATE($M16,MONTH(1&$N16),$O16) -> 24359 | Q16: =DATEDIF($P16,DATE(2023,6,8),"Y") -> 56 | R16: 0 | S16: 11090.72 | T16: tier - 3 | U16: tier - 1 | V16: R1013
A17: Id1011 | B17: 28.12 | C17: {=_xlfn.IFS($B17<18.5,"Underweight",$B17<24.9,"Normal Weight",$B17<29.9,"Overweight",TRUE,"Obesity")} -> Overweight | D17: 4.67 | E17: =IF($D17<5.7,"Normal",IF($D17<6.5,"Prediabetes","Diabetes")) -> Normal | F17: No | G17: No | H17: No | I17: 2 | J17: No | L17: Id1011 | M17: 1972 | N17: Oct | O17: 7 | P17: =DATE($M17,MONTH(1&$N17),$O17) -> 26579 | Q17: =DATEDIF($P17,DATE(2023,6,8),"Y") -> 50 | R17: 3 | S17: 11085.59 | T17: tier - 3 | U17: tier - 2 | V17: R1012 | X17: 4) Create a new column named “Weight Status” that categorizes BMI into different categories as below:
A18: Id1012 | B18: 26.98 | C18: {=_xlfn.IFS($B18<18.5,"Underweight",$B18<24.9,"Normal Weight",$B18<29.9,"Overweight",TRUE,"Obesity")} -> Overweight | D18: 9.81 | E18: =IF($D18<5.7,"Normal",IF($D18<6.5,"Prediabetes","Diabetes")) -> Diabetes | F18: Yes | G18: No | H18: No | I18: 0 | J18: No | L18: Id1012 | M18: 1967 | N18: Sep | O18: 4 | P18: =DATE($M18,MONTH(1&$N18),$O18) -> 24719 | Q18: =DATEDIF($P18,DATE(2023,6,8),"Y") -> 55 | R18: 0 | S18: 11082.58 | T18: tier - 3 | U18: tier - 2 | V18: R1012 | X18: 5) Create a new column named “Diabetes Status” and fill it as per the information given below:
A19: Id1013 | B19: 27.2 | C19: {=_xlfn.IFS($B19<18.5,"Underweight",$B19<24.9,"Normal Weight",$B19<29.9,"Overweight",TRUE,"Obesity")} -> Overweight | D19: 6.06 | E19: =IF($D19<5.7,"Normal",IF($D19<6.5,"Prediabetes","Diabetes")) -> Prediabetes | F19: Yes | G19: No | H19: No | I19: 2 | J19: No | L19: Id1013 | M19: 1966 | N19: Nov | O19: 20 | P19: =DATE($M19,MONTH(1&$N19),$O19) -> 24431 | Q19: =DATEDIF($P19,DATE(2023,6,8),"Y") -> 56 | R19: 0 | S19: 11073.18 | T19: tier - 3 | U19: tier - 3 | V19: R1011 | X19: Check C and E Columns
A20: Id1014 | B20: 25.3 | C20: {=_xlfn.IFS($B20<18.5,"Underweight",$B20<24.9,"Normal Weight",$B20<29.9,"Overweight",TRUE,"Obesity")} -> Overweight | D20: 5.19 | E20: =IF($D20<5.7,"Normal",IF($D20<6.5,"Prediabetes","Diabetes")) -> Normal | F20: Yes | G20: No | H20: No | I20: 2 | J20: No | L20: Id1014 | M20: 1966 | N20: Nov | O20: 7 | P20: =DATE($M20,MONTH(1&$N20),$O20) -> 24418 | Q20: =DATEDIF($P20,DATE(2023,6,8),"Y") -> 56 | R20: 0 | S20: 11070.54 | T20: tier - 3 | U20: tier - 3 | V20: R1011
A21: Id1015 | B21: 30.25 | C21: {=_xlfn.IFS($B21<18.5,"Underweight",$B21<24.9,"Normal Weight",$B21<29.9,"Overweight",TRUE,"Obesity")} -> Obesity | D21: 10.16 | E21: =IF($D21<5.7,"Normal",IF($D21<6.5,"Prediabetes","Diabetes")) -> Diabetes | F21: No | G21: No | H21: No | I21: 0 | J21: No | L21: Id1015 | M21: 1971 | N21: Nov | O21: 9 | P21: =DATE($M21,MONTH(1&$N21),$O21) -> 26246 | Q21: =DATEDIF($P21,DATE(2023,6,8),"Y") -> 51 | R21: 0 | S21: 11068.77 | T21: tier - 3 | U21: tier - 2 | V21: R1012 | X21: 6) Merge ‘year’, ‘month’ and ‘date’ columns in the “Hospitalization Details” Table into one column named ‘Date of Birth’ and format it in ‘DD-MMM-YYYY’ custom format.
A22: Id1016 | B22: 54 | C22: {=_xlfn.IFS($B22<18.5,"Underweight",$B22<24.9,"Normal Weight",$B22<29.9,"Overweight",TRUE,"Obesity")} -> Obesity | D22: 4.68 | E22: =IF($D22<5.7,"Normal",IF($D22<6.5,"Prediabetes","Diabetes")) -> Normal | F22: Yes | G22: yes | H22: No | I22: 2 | J22: No | L22: Id1016 | M22: 2000 | N22: Sep | O22: 18 | P22: =DATE($M22,MONTH(1&$N22),$O22) -> 36787 | Q22: =DATEDIF($P22,DATE(2023,6,8),"Y") -> 22 | R22: 0 | S22: 11068.7 | T22: tier - 3 | U22: tier - 1 | V22: R1011 | X22: Check Column "P"
A23: Id1017 | B23: 51.86 | C23: {=_xlfn.IFS($B23<18.5,"Underweight",$B23<24.9,"Normal Weight",$B23<29.9,"Overweight",TRUE,"Obesity")} -> Obesity | D23: 5.32 | E23: =IF($D23<5.7,"Normal",IF($D23<6.5,"Prediabetes","Diabetes")) -> Normal | F23: Yes | G23: No | H23: No | I23: 0 | J23: No | L23: Id1017 | M23: 2001 | N23: Dec | O23: 17 | P23: =DATE($M23,MONTH(1&$N23),$O23) -> 37242 | Q23: =DATEDIF($P23,DATE(2023,6,8),"Y") -> 21 | R23: 0 | S23: 11046.02 | T23: tier - 3 | U23: tier - 1 | V23: R1026
A24: Id1018 | B24: 31.39 | C24: {=_xlfn.IFS($B24<18.5,"Underweight",$B24<24.9,"Normal Weight",$B24<29.9,"Overweight",TRUE,"Obesity")} -> Obesity | D24: 6.99 | E24: =IF($D24<5.7,"Normal",IF($D24<6.5,"Prediabetes","Diabetes")) -> Diabetes | F24: No | G24: No | H24: No | I24: 0 | J24: No | L24: Id1018 | M24: 1974 | N24: Aug | O24: 30 | P24: =DATE($M24,MONTH(1&$N24),$O24) -> 27271 | Q24: =DATEDIF($P24,DATE(2023,6,8),"Y") -> 48 | R24: 0 | S24: 11037.85 | T24: tier - 3 | U24: tier - 2 | V24: R1025 | X24: 8) Format ‘charges’ column as currency ($).
A25: Id1019 | B25: 39.97 | C25: {=_xlfn.IFS($B25<18.5,"Underweight",$B25<24.9,"Normal Weight",$B25<29.9,"Overweight",TRUE,"Obesity")} -> Obesity | D25: 5.55 | E25: =IF($D25<5.7,"Normal",IF($D25<6.5,"Prediabetes","Diabetes")) -> Normal | F25: No | G25: No | H25: No | I25: 0 | J25: No | L25: Id1019 | M25: 1989 | N25: Oct | O25: 25 | P25: =DATE($M25,MONTH(1&$N25),$O25) -> 32806 | Q25: =DATEDIF($P25,DATE(2023,6,8),"Y") -> 33 | R25: 3 | S25: 11037.51 | T25: tier - 3 | U25: tier - 1 | V25: R1012 | X25: Check Column "S"
A26: Id102 | B26: 53.81 | C26: {=_xlfn.IFS($B26<18.5,"Underweight",$B26<24.9,"Normal Weight",$B26<29.9,"Overweight",TRUE,"Obesity")} -> Obesity | D26: 8.77 | E26: =IF($D26<5.7,"Normal",IF($D26<6.5,"Prediabetes","Diabetes")) -> Diabetes | F26: Yes | G26: No | H26: No | I26: 0 | J26: Yes | L26: Id102 | M26: 1981 | N26: Jul | O26: 28 | P26: =DATE($M26,MONTH(1&$N26),$O26) -> 29795 | Q26: =DATEDIF($P26,DATE(2023,6,8),"Y") -> 41 | R26: 1 | S26: 40208.56 | T26: tier - 1 | U26: tier - 2 | V26: R1011
A27: Id1020 | B27: 41.23 | C27: {=_xlfn.IFS($B27<18.5,"Underweight",$B27<24.9,"Normal Weight",$B27<29.9,"Overweight",TRUE,"Obesity")} -> Obesity | D27: 6.94 | E27: =IF($D27<5.7,"Normal",IF($D27<6.5,"Prediabetes","Diabetes")) -> Diabetes | F27: No | G27: No | H27: No | I27: 0 | J27: No | L27: Id1020 | M27: 1974 | N27: Dec | O27: 10 | P27: =DATE($M27,MONTH(1&$N27),$O27) -> 27373 | Q27: =DATEDIF($P27,DATE(2023,6,8),"Y") -> 48 | R27: 4 | S27: 11033.66 | T27: tier - 3 | U27: tier - 3 | V27: R1012
A28: Id1021 | B28: 49.45 | C28: {=_xlfn.IFS($B28<18.5,"Underweight",$B28<24.9,"Normal Weight",$B28<29.9,"Overweight",TRUE,"Obesity")} -> Obesity | D28: 4.2 | E28: =IF($D28<5.7,"Normal",IF($D28<6.5,"Prediabetes","Diabetes")) -> Normal | F28: Yes | G28: No | H28: No | I28: 0 | J28: No | L28: Id1021 | M28: 1996 | N28: Jul | O28: 21 | P28: =DATE($M28,MONTH(1&$N28),$O28) -> 35267 | Q28: =DATEDIF($P28,DATE(2023,6,8),"Y") -> 26 | R28: 0 | S28: 11028.56 | T28: tier - 3 | U28: tier - 3 | V28: R1012
A29: Id1022 | B29: 41.04 | C29: {=_xlfn.IFS($B29<18.5,"Underweight",$B29<24.9,"Normal Weight",$B29<29.9,"Overweight",TRUE,"Obesity")} -> Obesity | D29: 5.59 | E29: =IF($D29<5.7,"Normal",IF($D29<6.5,"Prediabetes","Diabetes")) -> Normal | F29: No | G29: No | H29: No | I29: 0 | J29: No | L29: Id1022 | M29: 1991 | N29: Jun | O29: 26 | P29: =DATE($M29,MONTH(1&$N29),$O29) -> 33415 | Q29: =DATEDIF($P29,DATE(2023,6,8),"Y") -> 31 | R29: 3 | S29: 11018.05 | T29: tier - 3 | U29: tier - 2 | V29: R1012
A30: Id1023 | B30: 27.93 | C30: {=_xlfn.IFS($B30<18.5,"Underweight",$B30<24.9,"Normal Weight",$B30<29.9,"Overweight",TRUE,"Obesity")} -> Overweight | D30: 9.96 | E30: =IF($D30<5.7,"Normal",IF($D30<6.5,"Prediabetes","Diabetes")) -> Diabetes | F30: No | G30: No | H30: No | I30: 0 | J30: No | L30: Id1023 | M30: 1974 | N30: Dec | O30: 15 | P30: =DATE($M30,MONTH(1&$N30),$O30) -> 27378 | Q30: =DATEDIF($P30,DATE(2023,6,8),"Y") -> 48 | R30: 4 | S30: 11015.17 | T30: tier - 3 | U30: tier - 1 | V30: R1012
A31: Id1024 | B31: 21.01 | C31: {=_xlfn.IFS($B31<18.5,"Underweight",$B31<24.9,"Normal Weight",$B31<29.9,"Overweight",TRUE,"Obesity")} -> Normal Weight | D31: 7.37 | E31: =IF($D31<5.7,"Normal",IF($D31<6.5,"Prediabetes","Diabetes")) -> Diabetes | F31: No | G31: No | H31: No | I31: 0 | J31: No | L31: Id1024 | M31: 1968 | N31: Oct | O31: 24 | P31: =DATE($M31,MONTH(1&$N31),$O31) -> 25135 | Q31: =DATEDIF($P31,DATE(2023,6,8),"Y") -> 54 | R31: 2 | S31: 11013.71 | T31: tier - 3 | U31: tier - 1 | V31: R1013
A32: Id1025 | B32: 52.37 | C32: {=_xlfn.IFS($B32<18.5,"Underweight",$B32<24.9,"Normal Weight",$B32<29.9,"Overweight",TRUE,"Obesity")} -> Obesity | D32: 5.06 | E32: =IF($D32<5.7,"Normal",IF($D32<6.5,"Prediabetes","Diabetes")) -> Normal | F32: Yes | G32: yes | H32: No | I32: 2 | J32: No | L32: Id1025 | M32: 2000 | N32: Sep | O32: 17 | P32: =DATE($M32,MONTH(1&$N32),$O32) -> 36786 | Q32: =DATEDIF($P32,DATE(2023,6,8),"Y") -> 22 | R32: 0 | S32: 10991.58 | T32: tier - 3 | U32: tier - 3 | V32: R1012
A33: Id1026 | B33: 40.37 | C33: {=_xlfn.IFS($B33<18.5,"Underweight",$B33<24.9,"Normal Weight",$B33<29.9,"Overweight",TRUE,"Obesity")} -> Obesity | D33: 8.21 | E33: =IF($D33<5.7,"Normal",IF($D33<6.5,"Prediabetes","Diabetes")) -> Diabetes | F33: No | G33: No | H33: No | I33: 0 | J33: No | L33: Id1026 | M33: 1965 | N33: Dec | O33: 18 | P33: =DATE($M33,MONTH(1&$N33),$O33) -> 24094 | Q33: =DATEDIF($P33,DATE(2023,6,8),"Y") -> 57 | R33: 0 | S33: 10982.5 | T33: tier - 3 | U33: tier - 3 | V33: R1013
A34: Id1027 | B34: 41.47 | C34: {=_xlfn.IFS($B34<18.5,"Underweight",$B34<24.9,"Normal Weight",$B34<29.9,"Overweight",TRUE,"Obesity")} -> Obesity | D34: 10.34 | E34: =IF($D34<5.7,"Normal",IF($D34<6.5,"Prediabetes","Diabetes")) -> Diabetes | F34: No | G34: No | H34: No | I34: 2 | J34: No | L34: Id1027 | M34: 1973 | N34: Oct | O34: 21 | P34: =DATE($M34,MONTH(1&$N34),$O34) -> 26958 | Q34: =DATEDIF($P34,DATE(2023,6,8),"Y") -> 49 | R34: 4 | S34: 10977.21 | T34: tier - 3 | U34: tier - 1 | V34: R1013
A35: Id1028 | B35: 33.725 | C35: {=_xlfn.IFS($B35<18.5,"Underweight",$B35<24.9,"Normal Weight",$B35<29.9,"Overweight",TRUE,"Obesity")} -> Obesity | D35: 5.51 | E35: =IF($D35<5.7,"Normal",IF($D35<6.5,"Prediabetes","Diabetes")) -> Normal | F35: Yes | G35: No | H35: No | I35: 2 | J35: No | L35: Id1028 | M35: 1966 | N35: Jul | O35: 9 | P35: =DATE($M35,MONTH(1&$N35),$O35) -> 24297 | Q35: =DATEDIF($P35,DATE(2023,6,8),"Y") -> 56 | R35: 0 | S35: 10976.25 | T35: tier - 3 | U35: tier - 2 | V35: R1012
A36: Id1029 | B36: 28.1 | C36: {=_xlfn.IFS($B36<18.5,"Underweight",$B36<24.9,"Normal Weight",$B36<29.9,"Overweight",TRUE,"Obesity")} -> Overweight | D36: 11.2 | E36: =IF($D36<5.7,"Normal",IF($D36<6.5,"Prediabetes","Diabetes")) -> Diabetes | F36: No | G36: No | H36: No | I36: 0 | J36: No | L36: Id1029 | M36: 1965 | N36: Jun | O36: 19 | P36: =DATE($M36,MONTH(1&$N36),$O36) -> 23912 | Q36: =DATEDIF($P36,DATE(2023,6,8),"Y") -> 57 | R36: 0 | S36: 10965.45 | T36: tier - 3 | U36: tier - 2 | V36: R1011
A37: Id103 | B37: 49.48 | C37: {=_xlfn.IFS($B37<18.5,"Underweight",$B37<24.9,"Normal Weight",$B37<29.9,"Overweight",TRUE,"Obesity")} -> Obesity | D37: 4.96 | E37: =IF($D37<5.7,"Normal",IF($D37<6.5,"Prediabetes","Diabetes")) -> Normal | F37: No | G37: No | H37: Yes | I37: 1 | J37: Yes | L37: Id103 | M37: 1979 | N37: Aug | O37: 18 | P37: =DATE($M37,MONTH(1&$N37),$O37) -> 29085 | Q37: =DATEDIF($P37,DATE(2023,6,8),"Y") -> 43 | R37: 2 | S37: 40204.83 | T37: tier - 1 | U37: tier - 3 | V37: R1012
... A2336: Id999 | B2336: 28.6 | C2336: {=_xlfn.IFS($B2336<18.5,"Underweight",$B2336<24.9,"Normal Weight",$B2336<29.9,"Overweight",TRUE,"Obesity")} -> Overweight | D2336: 5.56 | E2336: =IF($D2336<5.7,"Normal",IF($D2336<6.5,"Prediabetes","Diabetes")) -> Normal | F2336: Yes | G2336: No | H2336: Yes | I2336: 1 | J2336: No | L2336: Id999 | M2336: 1969 | N2336: Aug | O2336: 20 | P2336: =DATE($M2336,MONTH(1&$N2336),$O2336) -> 25435 | Q2336: =DATEDIF($P2336,DATE(2023,6,8),"Y") -> 53 | R2336: 3 | S2336: 11253.42 | T2336: tier - 3 | U2336: tier - 1 | V2336: R1011
X3186: Id2340
X3187: Id2341
...

Sheet Uniqee Value
A1: Id2336 | B1: 1999 | C1: Jun | D1: 9 | E1: =DATE($B1,MONTH(1&$C1),$D1) -> 36320 | F1: =DATEDIF($E1,DATE(2023,6,8),"Y") -> 23 | G1: 1 | H1: 2775.19 | I1: tier - 2 | J1: tier - 1 | K1: R1012
A2: Id2337 | B2: 1985 | C2: Dec | D2: 20 | E2: =DATE($B2,MONTH(1&$C2),$D2) -> 31401 | F2: =DATEDIF($E2,DATE(2023,6,8),"Y") -> 37 | G2: 2 | H2: 6203.9 | I2: tier - 1 | J2: tier - 2 | K2: R1012
A3: Id2338 | B3: 2000 | C3: Oct | D3: 13 | E3: =DATE($B3,MONTH(1&$C3),$D3) -> 36812 | F3: =DATEDIF($E3,DATE(2023,6,8),"Y") -> 22 | G3: 0 | H3: 35585.58 | I3: tier - 1 | J3: tier - 2 | K3: R1011
A4: Id2339 | B4: 1992 | C4: Oct | D4: 6 | E4: =DATE($B4,MONTH(1&$C4),$D4) -> 33883 | F4: =DATEDIF($E4,DATE(2023,6,8),"Y") -> 30 | G4: 0 | H4: 36837.47 | I4: tier - 1 | J4: tier - 2 | K4: R1011
A5: Id2341 | B5: 2004 | C5: Nov | D5: 6 | E5: =DATE($B5,MONTH(1&$C5),$D5) -> 38297 | F5: =DATEDIF($E5,DATE(2023,6,8),"Y") -> 18 | G5: 0 | H5: 1137.01 | I5: tier - 3 | J5: tier - 1 | K5: R1013
A6: id2342 | B6: 1987 | C6: Nov | D6: 27 | E6: =DATE($B6,MONTH(1&$C6),$D6) -> 32108 | F6: =DATEDIF($E6,DATE(2023,6,8),"Y") -> 35 | G6: 2 | H6: 20984.09 | I6: tier - 2 | J6: tier - 2 | K6: R1015
A7: Id2340 | B7: 1991 | C7: Nov | D7: 22 | E7: =DATE($B7,MONTH(1&$C7),$D7) -> 33564 | F7: =DATEDIF($E7,DATE(2023,6,8),"Y") -> 31 | G7: 2 | H7: 38711 | I7: tier - 1 | J7: tier - 3 | K7: R1011

Sheet Healthcare
A1: Customer ID | B1: State ID | C1: Date of Birth | D1: Age | E1: First Name | F1: BMI | G1: Weight Status | H1: HBA1C | I1: Diabetes Status | J1: Heart Issues | K1: Any Transplants | L1: Cancer history | M1: smoker | N1: Number Of Maj or Surgeries | O1: Hospital tier | P1: City tier | Q1: charges
A2: Id1 | B2: =VLOOKUP($A2,'Data Transformation Q1 to Q8'!A:V,22,FALSE) -> R1013 | C2: =VLOOKUP($A2,'Data Transformation Q1 to Q8'!$A:$V,16,FALSE) -> 25123 | D2: =VLOOKUP($A2,'Data Transformation Q1 to Q8'!$A:$V,17,FALSE) -> 54 | E2: =VLOOKUP(A2,'Customer Names'!A:D,3,FALSE) -> Kelly | F2: =VLOOKUP($A2,'Data Transformation Q1 to Q8'!$A:$V,2,FALSE) -> 47.41 | G2: =VLOOKUP($A2,'Data Transformation Q1 to Q8'!$A:$V,3,FALSE) -> Obesity | H2: =VLOOKUP($A2,'Data Transformation Q1 to Q8'!$A:$V,4,FALSE) -> 7.47 | I2: =VLOOKUP($A2,'Data Transformation Q1 to Q8'!$A:$V,5,FALSE) -> Diabetes | J2: =VLOOKUP($A2,'Data Transformation Q1 to Q8'!$A:$V,6,FALSE) -> No | K2: =VLOOKUP($A2,'Data Transformation Q1 to Q8'!$A:$V,7,FALSE) -> No | L2: =VLOOKUP($A2,'Data Transformation Q1 to Q8'!$A:$V,8,FALSE) -> No | M2: =VLOOKUP($A2,'Data Transformation Q1 to Q8'!$A:$V,10,FALSE) -> Yes | N2: =VLOOKUP($A2,'Data Transformation Q1 to Q8'!$A:$V,9,FALSE) -> 0 | O2: =VLOOKUP($A2,'Data Transformation Q1 to Q8'!$A:$V,20,FALSE) -> tier - 1 | P2: =VLOOKUP($A2,'Data Transformation Q1 to Q8'!$A:$V,21,FALSE) -> tier - 3 | Q2: =VLOOKUP($A2,'Data Transformation Q1 to Q8'!$A:$V,19,FALSE) -> 63770.43
A3: Id2 | B3: =VLOOKUP(A3,'Data Transformation Q1 to Q8'!A:V,22,FALSE) -> R1013 | C3: =VLOOKUP($A3,'Data Transformation Q1 to Q8'!$A:$V,16,FALSE) -> 28284 | D3: =VLOOKUP($A3,'Data Transformation Q1 to Q8'!$A:$V,17,FALSE) -> 46 | E3: =VLOOKUP(A3,'Customer Names'!A:D,3,FALSE) -> Matthew D | F3: =VLOOKUP($A3,'Data Transformation Q1 to Q8'!$A:$V,2,FALSE) -> 30.36 | G3: =VLOOKUP($A3,'Data Transformation Q1 to Q8'!$A:$V,3,FALSE) -> Obesity | H3: =VLOOKUP($A3,'Data Transformation Q1 to Q8'!$A:$V,4,FALSE) -> 5.77 | I3: =VLOOKUP($A3,'Data Transformation Q1 to Q8'!$A:$V,5,FALSE) -> Prediabetes | J3: =VLOOKUP($A3,'Data Transformation Q1 to Q8'!$A:$V,6,FALSE) -> No | K3: =VLOOKUP($A3,'Data Transformation Q1 to Q8'!$A:$V,7,FALSE) -> No | L3: =VLOOKUP($A3,'Data Transformation Q1 to Q8'!$A:$V,8,FALSE) -> No | M3: =VLOOKUP($A3,'Data Transformation Q1 to Q8'!$A:$V,10,FALSE) -> Yes | N3: =VLOOKUP($A3,'Data Transformation Q1 to Q8'!$A:$V,9,FALSE) -> 0 | O3: =VLOOKUP($A3,'Data Transformation Q1 to Q8'!$A:$V,20,FALSE) -> tier - 2 | P3: =VLOOKUP($A3,'Data Transformation Q1 to Q8'!$A:$V,21,FALSE) -> tier - 3 | Q3: =VLOOKUP($A3,'Data Transformation Q1 to Q8'!$A:$V,19,FALSE) -> 62592.87
A4: Id3 | B4: =VLOOKUP(A4,'Data Transformation Q1 to Q8'!A:V,22,FALSE) -> R1012 | C4: =VLOOKUP($A4,'Data Transformation Q1 to Q8'!$A:$V,16,FALSE) -> 25822 | D4: =VLOOKUP($A4,'Data Transformation Q1 to Q8'!$A:$V,17,FALSE) -> 52 | E4: =VLOOKUP(A4,'Customer Names'!A:D,3,FALSE) -> Phil | F4: =VLOOKUP($A4,'Data Transformation Q1 to Q8'!$A:$V,2,FALSE) -> 34.485 | G4: =VLOOKUP($A4,'Data Transformation Q1 to Q8'!$A:$V,3,FALSE) -> Obesity | H4: =VLOOKUP($A4,'Data Transformation Q1 to Q8'!$A:$V,4,FALSE) -> 11.87 | I4: =VLOOKUP($A4,'Data Transformation Q1 to Q8'!$A:$V,5,FALSE) -> Diabetes | J4: =VLOOKUP($A4,'Data Transformation Q1 to Q8'!$A:$V,6,FALSE) -> Yes | K4: =VLOOKUP($A4,'Data Transformation Q1 to Q8'!$A:$V,7,FALSE) -> No | L4: =VLOOKUP($A4,'Data Transformation Q1 to Q8'!$A:$V,8,FALSE) -> No | M4: =VLOOKUP($A4,'Data Transformation Q1 to Q8'!$A:$V,10,FALSE) -> Yes | N4: =VLOOKUP($A4,'Data Transformation Q1 to Q8'!$A:$V,9,FALSE) -> 2 | O4: =VLOOKUP($A4,'Data Transformation Q1 to Q8'!$A:$V,20,FALSE) -> tier - 1 | P4: =VLOOKUP($A4,'Data Transformation Q1 to Q8'!$A:$V,21,FALSE) -> tier - 1 | Q4: =VLOOKUP($A4,'Data Transformation Q1 to Q8'!$A:$V,19,FALSE) -> 60021.4
A5: Id4 | B5: =VLOOKUP(A5,'Data Transformation Q1 to Q8'!A:V,22,FALSE) -> R1024 | C5: =VLOOKUP($A5,'Data Transformation Q1 to Q8'!$A:$V,16,FALSE) -> 33395 | D5: =VLOOKUP($A5,'Data Transformation Q1 to Q8'!$A:$V,17,FALSE) -> 32 | E5: =VLOOKUP(A5,'Customer Names'!A:D,3,FALSE) -> Kelsey | F5: =VLOOKUP($A5,'Data Transformation Q1 to Q8'!$A:$V,2,FALSE) -> 38.095 | G5: =VLOOKUP($A5,'Data Transformation Q1 to Q8'!$A:$V,3,FALSE) -> Obesity | H5: =VLOOKUP($A5,'Data Transformation Q1 to Q8'!$A:$V,4,FALSE) -> 6.05 | I5: =VLOOKUP($A5,'Data Transformation Q1 to Q8'!$A:$V,5,FALSE) -> Prediabetes | J5: =VLOOKUP($A5,'Data Transformation Q1 to Q8'!$A:$V,6,FALSE) -> No | K5: =VLOOKUP($A5,'Data Transformation Q1 to Q8'!$A:$V,7,FALSE) -> No | L5: =VLOOKUP($A5,'Data Transformation Q1 to Q8'!$A:$V,8,FALSE) -> No | M5: =VLOOKUP($A5,'Data Transformation Q1 to Q8'!$A:$V,10,FALSE) -> Yes | N5: =VLOOKUP($A5,'Data Transformation Q1 to Q8'!$A:$V,9,FALSE) -> 0 | O5: =VLOOKUP($A5,'Data Transformation Q1 to Q8'!$A:$V,20,FALSE) -> tier - 1 | P5: =VLOOKUP($A5,'Data Transformation Q1 to Q8'!$A:$V,21,FALSE) -> tier - 3 | Q5: =VLOOKUP($A5,'Data Transformation Q1 to Q8'!$A:$V,19,FALSE) -> 58571.07
A6: Id5 | B6: =VLOOKUP(A6,'Data Transformation Q1 to Q8'!A:V,22,FALSE) -> R1012 | C6: =VLOOKUP($A6,'Data Transformation Q1 to Q8'!$A:$V,16,FALSE) -> 32678 | D6: =VLOOKUP($A6,'Data Transformation Q1 to Q8'!$A:$V,17,FALSE) -> 33 | E6: =VLOOKUP(A6,'Customer Names'!A:D,3,FALSE) -> Kristyn | F6: =VLOOKUP($A6,'Data Transformation Q1 to Q8'!$A:$V,2,FALSE) -> 35.53 | G6: =VLOOKUP($A6,'Data Transformation Q1 to Q8'!$A:$V,3,FALSE) -> Obesity | H6: =VLOOKUP($A6,'Data Transformation Q1 to Q8'!$A:$V,4,FALSE) -> 5.45 | I6: =VLOOKUP($A6,'Data Transformation Q1 to Q8'!$A:$V,5,FALSE) -> Normal | J6: =VLOOKUP($A6,'Data Transformation Q1 to Q8'!$A:$V,6,FALSE) -> No | K6: =VLOOKUP($A6,'Data Transformation Q1 to Q8'!$A:$V,7,FALSE) -> No | L6: =VLOOKUP($A6,'Data Transformation Q1 to Q8'!$A:$V,8,FALSE) -> No | M6: =VLOOKUP($A6,'Data Transformation Q1 to Q8'!$A:$V,10,FALSE) -> Yes | N6: =VLOOKUP($A6,'Data Transformation Q1 to Q8'!$A:$V,9,FALSE) -> 0 | O6: =VLOOKUP($A6,'Data Transformation Q1 to Q8'!$A:$V,20,FALSE) -> tier - 1 | P6: =VLOOKUP($A6,'Data Transformation Q1 to Q8'!$A:$V,21,FALSE) -> tier - 2 | Q6: =VLOOKUP($A6,'Data Transformation Q1 to Q8'!$A:$V,19,FALSE) -> 55135.4
A7: Id6 | B7: =VLOOKUP(A7,'Data Transformation Q1 to Q8'!A:V,22,FALSE) -> R1011 | C7: =VLOOKUP($A7,'Data Transformation Q1 to Q8'!$A:$V,16,FALSE) -> 22862 | D7: =VLOOKUP($A7,'Data Transformation Q1 to Q8'!$A:$V,17,FALSE) -> 60 | E7: =VLOOKUP(A7,'Customer Names'!A:D,3,FALSE) -> Russell B | F7: =VLOOKUP($A7,'Data Transformation Q1 to Q8'!$A:$V,2,FALSE) -> 32.8 | G7: =VLOOKUP($A7,'Data Transformation Q1 to Q8'!$A:$V,3,FALSE) -> Obesity | H7: =VLOOKUP($A7,'Data Transformation Q1 to Q8'!$A:$V,4,FALSE) -> 6.59 | I7: =VLOOKUP($A7,'Data Transformation Q1 to Q8'!$A:$V,5,FALSE) -> Diabetes | J7: =VLOOKUP($A7,'Data Transformation Q1 to Q8'!$A:$V,6,FALSE) -> No | K7: =VLOOKUP($A7,'Data Transformation Q1 to Q8'!$A:$V,7,FALSE) -> No | L7: =VLOOKUP($A7,'Data Transformation Q1 to Q8'!$A:$V,8,FALSE) -> No | M7: =VLOOKUP($A7,'Data Transformation Q1 to Q8'!$A:$V,10,FALSE) -> Yes | N7: =VLOOKUP($A7,'Data Transformation Q1 to Q8'!$A:$V,9,FALSE) -> 0 | O7: =VLOOKUP($A7,'Data Transformation Q1 to Q8'!$A:$V,20,FALSE) -> tier - 1 | P7: =VLOOKUP($A7,'Data Transformation Q1 to Q8'!$A:$V,21,FALSE) -> tier - 3 | Q7: =VLOOKUP($A7,'Data Transformation Q1 to Q8'!$A:$V,19,FALSE) -> 52590.83
A8: Id7 | B8: =VLOOKUP(A8,'Data Transformation Q1 to Q8'!A:V,22,FALSE) -> R1011 | C8: =VLOOKUP($A8,'Data Transformation Q1 to Q8'!$A:$V,16,FALSE) -> 34634 | D8: =VLOOKUP($A8,'Data Transformation Q1 to Q8'!$A:$V,17,FALSE) -> 28 | E8: =VLOOKUP(A8,'Customer Names'!A:D,3,FALSE) -> Scott | F8: =VLOOKUP($A8,'Data Transformation Q1 to Q8'!$A:$V,2,FALSE) -> 36.4 | G8: =VLOOKUP($A8,'Data Transformation Q1 to Q8'!$A:$V,3,FALSE) -> Obesity | H8: =VLOOKUP($A8,'Data Transformation Q1 to Q8'!$A:$V,4,FALSE) -> 6.07 | I8: =VLOOKUP($A8,'Data Transformation Q1 to Q8'!$A:$V,5,FALSE) -> Prediabetes | J8: =VLOOKUP($A8,'Data Transformation Q1 to Q8'!$A:$V,6,FALSE) -> No | K8: =VLOOKUP($A8,'Data Transformation Q1 to Q8'!$A:$V,7,FALSE) -> No | L8: =VLOOKUP($A8,'Data Transformation Q1 to Q8'!$A:$V,8,FALSE) -> No | M8: =VLOOKUP($A8,'Data Transformation Q1 to Q8'!$A:$V,10,FALSE) -> Yes | N8: =VLOOKUP($A8,'Data Transformation Q1 to Q8'!$A:$V,9,FALSE) -> 0 | O8: =VLOOKUP($A8,'Data Transformation Q1 to Q8'!$A:$V,20,FALSE) -> tier - 1 | P8: =VLOOKUP($A8,'Data Transformation Q1 to Q8'!$A:$V,21,FALSE) -> tier - 3 | Q8: =VLOOKUP($A8,'Data Transformation Q1 to Q8'!$A:$V,19,FALSE) -> 51194.56
A9: Id8 | B9: =VLOOKUP(A9,'Data Transformation Q1 to Q8'!A:V,22,FALSE) -> R1013 | C9: =VLOOKUP($A9,'Data Transformation Q1 to Q8'!$A:$V,16,FALSE) -> 21363 | D9: =VLOOKUP($A9,'Data Transformation Q1 to Q8'!$A:$V,17,FALSE) -> 64 | E9: =VLOOKUP(A9,'Customer Names'!A:D,3,FALSE) -> Stephen | F9: =VLOOKUP($A9,'Data Transformation Q1 to Q8'!$A:$V,2,FALSE) -> 36.96 | G9: =VLOOKUP($A9,'Data Transformation Q1 to Q8'!$A:$V,3,FALSE) -> Obesity | H9: =VLOOKUP($A9,'Data Transformation Q1 to Q8'!$A:$V,4,FALSE) -> 7.93 | I9: =VLOOKUP($A9,'Data Transformation Q1 to Q8'!$A:$V,5,FALSE) -> Diabetes | J9: =VLOOKUP($A9,'Data Transformation Q1 to Q8'!$A:$V,6,FALSE) -> No | K9: =VLOOKUP($A9,'Data Transformation Q1 to Q8'!$A:$V,7,FALSE) -> No | L9: =VLOOKUP($A9,'Data Transformation Q1 to Q8'!$A:$V,8,FALSE) -> No | M9: =VLOOKUP($A9,'Data Transformation Q1 to Q8'!$A:$V,10,FALSE) -> Yes | N9: =VLOOKUP($A9,'Data Transformation Q1 to Q8'!$A:$V,9,FALSE) -> 3 | O9: =VLOOKUP($A9,'Data Transformation Q1 to Q8'!$A:$V,20,FALSE) -> tier - 2 | P9: =VLOOKUP($A9,'Data Transformation Q1 to Q8'!$A:$V,21,FALSE) -> tier - 2 | Q9: =VLOOKUP($A9,'Data Transformation Q1 to Q8'!$A:$V,19,FALSE) -> 49577.66
A10: Id9 | B10: =VLOOKUP(A10,'Data Transformation Q1 to Q8'!A:V,22,FALSE) -> R1013 | C10: =VLOOKUP($A10,'Data Transformation Q1 to Q8'!$A:$V,16,FALSE) -> 23258 | D10: =VLOOKUP($A10,'Data Transformation Q1 to Q8'!$A:$V,17,FALSE) -> 59 | E10: =VLOOKUP(A10,'Customer Names'!A:D,3,FALSE) -> Patrick R | F10: =VLOOKUP($A10,'Data Transformation Q1 to Q8'!$A:$V,2,FALSE) -> 41.14 | G10: =VLOOKUP($A10,'Data Transformation Q1 to Q8'!$A:$V,3,FALSE) -> Obesity | H10: =VLOOKUP($A10,'Data Transformation Q1 to Q8'!$A:$V,4,FALSE) -> 9.58 | I10: =VLOOKUP($A10,'Data Transformation Q1 to Q8'!$A:$V,5,FALSE) -> Diabetes | J10: =VLOOKUP($A10,'Data Transformation Q1 to Q8'!$A:$V,6,FALSE) -> Yes | K10: =VLOOKUP($A10,'Data Transformation Q1 to Q8'!$A:$V,7,FALSE) -> No | L10: =VLOOKUP($A10,'Data Transformation Q1 to Q8'!$A:$V,8,FALSE) -> Yes | M10: =VLOOKUP($A10,'Data Transformation Q1 to Q8'!$A:$V,10,FALSE) -> Yes | N10: =VLOOKUP($A10,'Data Transformation Q1 to Q8'!$A:$V,9,FALSE) -> 1 | O10: =VLOOKUP($A10,'Data Transformation Q1 to Q8'!$A:$V,20,FALSE) -> tier - 1 | P10: =VLOOKUP($A10,'Data Transformation Q1 to Q8'!$A:$V,21,FALSE) -> tier - 2 | Q10: =VLOOKUP($A10,'Data Transformation Q1 to Q8'!$A:$V,19,FALSE) -> 48970.25
A11: Id10 | B11: =VLOOKUP(A11,'Data Transformation Q1 to Q8'!A:V,22,FALSE) -> R1013 | C11: =VLOOKUP($A11,'Data Transformation Q1 to Q8'!$A:$V,16,FALSE) -> 28853 | D11: =VLOOKUP($A11,'Data Transformation Q1 to Q8'!$A:$V,17,FALSE) -> 44 | E11: =VLOOKUP(A11,'Customer Names'!A:D,3,FALSE) -> Brooke N | F11: =VLOOKUP($A11,'Data Transformation Q1 to Q8'!$A:$V,2,FALSE) -> 38.06 | G11: =VLOOKUP($A11,'Data Transformation Q1 to Q8'!$A:$V,3,FALSE) -> Obesity | H11: =VLOOKUP($A11,'Data Transformation Q1 to Q8'!$A:$V,4,FALSE) -> 10.79 | I11: =VLOOKUP($A11,'Data Transformation Q1 to Q8'!$A:$V,5,FALSE) -> Diabetes | J11: =VLOOKUP($A11,'Data Transformation Q1 to Q8'!$A:$V,6,FALSE) -> No | K11: =VLOOKUP($A11,'Data Transformation Q1 to Q8'!$A:$V,7,FALSE) -> No | L11: =VLOOKUP($A11,'Data Transformation Q1 to Q8'!$A:$V,8,FALSE) -> No | M11: =VLOOKUP($A11,'Data Transformation Q1 to Q8'!$A:$V,10,FALSE) -> Yes | N11: =VLOOKUP($A11,'Data Transformation Q1 to Q8'!$A:$V,9,FALSE) -> 0 | O11: =VLOOKUP($A11,'Data Transformation Q1 to Q8'!$A:$V,20,FALSE) -> tier - 1 | P11: =VLOOKUP($A11,'Data Transformation Q1 to Q8'!$A:$V,21,FALSE) -> tier - 2 | Q11: =VLOOKUP($A11,'Data Transformation Q1 to Q8'!$A:$V,19,FALSE) -> 48885.14
A12: Id11 | B12: =VLOOKUP(A12,'Data Transformation Q1 to Q8'!A:V,22,FALSE) -> R1011 | C12: =VLOOKUP($A12,'Data Transformation Q1 to Q8'!$A:$V,16,FALSE) -> 21753 | D12: =VLOOKUP($A12,'Data Transformation Q1 to Q8'!$A:$V,17,FALSE) -> 63 | E12: =VLOOKUP(A12,'Customer Names'!A:D,3,FALSE) -> Paola Andrea | F12: =VLOOKUP($A12,'Data Transformation Q1 to Q8'!$A:$V,2,FALSE) -> 37.7 | G12: =VLOOKUP($A12,'Data Transformation Q1 to Q8'!$A:$V,3,FALSE) -> Obesity | H12: =VLOOKUP($A12,'Data Transformation Q1 to Q8'!$A:$V,4,FALSE) -> 5.96 | I12: =VLOOKUP($A12,'Data Transformation Q1 to Q8'!$A:$V,5,FALSE) -> Prediabetes | J12: =VLOOKUP($A12,'Data Transformation Q1 to Q8'!$A:$V,6,FALSE) -> Yes | K12: =VLOOKUP($A12,'Data Transformation Q1 to Q8'!$A:$V,7,FALSE) -> No | L12: =VLOOKUP($A12,'Data Transformation Q1 to Q8'!$A:$V,8,FALSE) -> No | M12: =VLOOKUP($A12,'Data Transformation Q1 to Q8'!$A:$V,10,FALSE) -> Yes | N12: =VLOOKUP($A12,'Data Transformation Q1 to Q8'!$A:$V,9,FALSE) -> 2 | O12: =VLOOKUP($A12,'Data Transformation Q1 to Q8'!$A:$V,20,FALSE) -> tier - 2 | P12: =VLOOKUP($A12,'Data Transformation Q1 to Q8'!$A:$V,21,FALSE) -> tier - 1 | Q12: =VLOOKUP($A12,'Data Transformation Q1 to Q8'!$A:$V,19,FALSE) -> 48824.45
A13: Id12 | B13: =VLOOKUP(A13,'Data Transformation Q1 to Q8'!A:V,22,FALSE) -> R1013 | C13: =VLOOKUP($A13,'Data Transformation Q1 to Q8'!$A:$V,16,FALSE) -> 24042 | D13: =VLOOKUP($A13,'Data Transformation Q1 to Q8'!$A:$V,17,FALSE) -> 57 | E13: =VLOOKUP(A13,'Customer Names'!A:D,3,FALSE) -> David | F13: =VLOOKUP($A13,'Data Transformation Q1 to Q8'!$A:$V,2,FALSE) -> 42.13 | G13: =VLOOKUP($A13,'Data Transformation Q1 to Q8'!$A:$V,3,FALSE) -> Obesity | H13: =VLOOKUP($A13,'Data Transformation Q1 to Q8'!$A:$V,4,FALSE) -> 11.9 | I13: =VLOOKUP($A13,'Data Transformation Q1 to Q8'!$A:$V,5,FALSE) -> Diabetes | J13: =VLOOKUP($A13,'Data Transformation Q1 to Q8'!$A:$V,6,FALSE) -> No | K13: =VLOOKUP($A13,'Data Transformation Q1 to Q8'!$A:$V,7,FALSE) -> No | L13: =VLOOKUP($A13,'Data Transformation Q1 to Q8'!$A:$V,8,FALSE) -> No | M13: =VLOOKUP($A13,'Data Transformation Q1 to Q8'!$A:$V,10,FALSE) -> Yes | N13: =VLOOKUP($A13,'Data Transformation Q1 to Q8'!$A:$V,9,FALSE) -> 0 | O13: =VLOOKUP($A13,'Data Transformation Q1 to Q8'!$A:$V,20,FALSE) -> tier - 1 | P13: =VLOOKUP($A13,'Data Transformation Q1 to Q8'!$A:$V,21,FALSE) -> tier - 2 | Q13: =VLOOKUP($A13,'Data Transformation Q1 to Q8'!$A:$V,19,FALSE) -> 48675.52
A14: Id13 | B14: =VLOOKUP(A14,'Data Transformation Q1 to Q8'!A:V,22,FALSE) -> R1013 | C14: =VLOOKUP($A14,'Data Transformation Q1 to Q8'!$A:$V,16,FALSE) -> 22930 | D14: =VLOOKUP($A14,'Data Transformation Q1 to Q8'!$A:$V,17,FALSE) -> 60 | E14: =VLOOKUP(A14,'Customer Names'!A:D,3,FALSE) -> Wade | F14: =VLOOKUP($A14,'Data Transformation Q1 to Q8'!$A:$V,2,FALSE) -> 40.92 | G14: =VLOOKUP($A14,'Data Transformation Q1 to Q8'!$A:$V,3,FALSE) -> Obesity | H14: =VLOOKUP($A14,'Data Transformation Q1 to Q8'!$A:$V,4,FALSE) -> 8.41 | I14: =VLOOKUP($A14,'Data Transformation Q1 to Q8'!$A:$V,5,FALSE) -> Diabetes | J14: =VLOOKUP($A14,'Data Transformation Q1 to Q8'!$A:$V,6,FALSE) -> No | K14: =VLOOKUP($A14,'Data Transformation Q1 to Q8'!$A:$V,7,FALSE) -> No | L14: =VLOOKUP($A14,'Data Transformation Q1 to Q8'!$A:$V,8,FALSE) -> No | M14: =VLOOKUP($A14,'Data Transformation Q1 to Q8'!$A:$V,10,FALSE) -> Yes | N14: =VLOOKUP($A14,'Data Transformation Q1 to Q8'!$A:$V,9,FALSE) -> 0 | O14: =VLOOKUP($A14,'Data Transformation Q1 to Q8'!$A:$V,20,FALSE) -> tier - 1 | P14: =VLOOKUP($A14,'Data Transformation Q1 to Q8'!$A:$V,21,FALSE) -> tier - 2 | Q14: =VLOOKUP($A14,'Data Transformation Q1 to Q8'!$A:$V,19,FALSE) -> 48673.56
... A2336: Id2335 | B2336: =VLOOKUP(A2336,'Data Transformation Q1 to Q8'!A:V,22,FALSE) -> R1013 | C2336: =VLOOKUP($A2336,'Data Transformation Q1 to Q8'!$A:$V,16,FALSE) -> 33794 | D2336: =VLOOKUP($A2336,'Data Transformation Q1 to Q8'!$A:$V,17,FALSE) -> 30 | E2336: =VLOOKUP(A2336,'Customer Names'!A:D,3,FALSE) -> Aaron K | F2336: =VLOOKUP($A2336,'Data Transformation Q1 to Q8'!$A:$V,2,FALSE) -> 17.58 | G2336: =VLOOKUP($A2336,'Data Transformation Q1 to Q8'!$A:$V,3,FALSE) -> Underweight | H2336: =VLOOKUP($A2336,'Data Transformation Q1 to Q8'!$A:$V,4,FALSE) -> 4.51 | I2336: =VLOOKUP($A2336,'Data Transformation Q1 to Q8'!$A:$V,5,FALSE) -> Normal | J2336: =VLOOKUP($A2336,'Data Transformation Q1 to Q8'!$A:$V,6,FALSE) -> No | K2336: =VLOOKUP($A2336,'Data Transformation Q1 to Q8'!$A:$V,7,FALSE) -> No | L2336: =VLOOKUP($A2336,'Data Transformation Q1 to Q8'!$A:$V,8,FALSE) -> No | M2336: =VLOOKUP($A2336,'Data Transformation Q1 to Q8'!$A:$V,10,FALSE) -> No | N2336: =VLOOKUP($A2336,'Data Transformation Q1 to Q8'!$A:$V,9,FALSE) -> 1 | O2336: =VLOOKUP($A2336,'Data Transformation Q1 to Q8'!$A:$V,20,FALSE) -> tier - 2 | P2336: =VLOOKUP($A2336,'Data Transformation Q1 to Q8'!$A:$V,21,FALSE) -> tier - 3 | Q2336: =VLOOKUP($A2336,'Data Transformation Q1 to Q8'!$A:$V,19,FALSE) -> 563.84

Sheet Pie or Donut Chart Q1
D5: ➢ What is the distribution of cancer history among smokers and non-smokers?
D8: Cancer history distribution by smoking status
D9: Cancer history | E9: Non-smoker | F9: Smoker | G9: Grand Total
D10: No | E10: =COUNTIFS(Healthcare!$L$2:$L$2336,$D10,Healthcare!$M$2:$M$2336,"No") -> 1540 | F10: =COUNTIFS(Healthcare!$L$2:$L$2336,$D10,Healthcare!$M$2:$M$2336,"Yes") -> 404 | G10: =SUM(E10:F10) -> 1944
D11: Yes | E11: =COUNTIFS(Healthcare!$L$2:$L$2336,$D11,Healthcare!$M$2:$M$2336,"No") -> 307 | F11: =COUNTIFS(Healthcare!$L$2:$L$2336,$D11,Healthcare!$M$2:$M$2336,"Yes") -> 84 | G11: =SUM(E11:F11) -> 391
D12: Grand Total | E12: =SUM(E10:E11) -> 1847 | F12: =SUM(F10:F11) -> 488 | G12: =SUM(G10:G11) -> 2335
B15: Cancer history | C15: Smoker | I15: Cancer history | J15: Non-smoker
B16: =D10 -> No | C16: =F10 -> 404 | I16: No | J16: =COUNTIFS(Healthcare!$L$2:$L$2336,$B16,Healthcare!$M$2:$M$2336,"No") -> 1540
B17: =D11 -> Yes | C17: =F11 -> 84 | I17: Yes | J17: =COUNTIFS(Healthcare!$L$2:$L$2336,$B17,Healthcare!$M$2:$M$2336,"No") -> 307
B37: Among smokers, 17.2% have a recorded cancer history, compared with 16.6% among non-smokers. The difference is small in this dataset, and these results alone do not establish that smoking causes cancer.

Sheet Pie or Donut Chart Q2
B2: ➢ How does the total number of major surgeries and average HbA1C differ between patients with and without a history of transplants?
C4: Patients transplant history | D4: Average of HBA1C | G4: Patients transplant history | H4: Sum of Number Of Maj or Surgeries
C5: No | D5: 6.6704427 | G5: No | H5: 1417
C6: yes | D6: 5.1876389 | G6: yes | H6: 162
C7: . | D7: 6.5789979 | G7: Total | H7: 1579
B24: Patients without a transplant history had 1,417 major surgeries in total, compared with 162 among patients with a transplant history. The average HbA1C was 6.67 for patients without a transplant history and 5.19 for those with a transplant history

Sheet Column or Bar Chart Q1
E3: ➢ How do healthcare charges vary based on different weight statuses and diabetes statuses?
F5: Average of charges | G5: Column Labels
F6: Weight Category | G6: Diabetes | H6: Normal | I6: Prediabetes | J6: Grand Total
F7: Normal Weight | G7: 12464.137 | H7: 7897.0779 | I7: 10492.131 | J7: 9842.5103
F8: Obesity | G8: 19263.853 | H8: 15126.605 | I8: 15246.557 | J8: 16591.49
F9: Overweight | G9: 14200.033 | H9: 10389.52 | I9: 9770.6945 | J9: 11430.313
F10: Underweight | G10: 7442.9649 | H10: 6911.0056 | I10: 5647.7483 | J10: 6899.3175
F11: Grand Total | G11: 16120.287 | H11: 12090.723 | I11: 12532.263 | J11: 13529.918

Sheet Column or Bar Chart Q2
E5: Can you compare the average charges for each hospital tier within different states?
C8: Average of charges | D8: Hospital tier
C9: State ID | D9: tier - 1 | E9: tier - 2 | F9: tier - 3 | G9: Grand Total
C10: R1011 | D10: 33081.374 | E10: 18997.281 | F10: 9250.3618 | G10: 19466.246
C11: R1012 | D11: 25954.076 | E11: 10334.279 | F11: 10179.942 | G11: 12047.601
C12: R1013 | D12: 31328.102 | E12: 8439.2844 | F12: 6890.7568 | G12: 10514.94
C13: R1014 | D13: 13891.86 | E13: 2395.17 | F13: 16950.485 | G13: 13478.057
C14: R1015 | D14: 21523.52 | E14: 15675.543 | F14: 7570.755 | G14: 13948.61
C15: R1016 | D15: 39868.616 | E15: 16075.963 | F15: 8133.0084 | G15: 13589.263
C16: R1017 | D16: 34070.596 | E16: 11365.622 | F16: 8667.3662 | G16: 14806.108
C17: R1018 | D17: 33475.82 | E17: 10139.553 | F17: 12570.97 | G17: 13272.787
C18: R1019 | D18: 27621.61 | E18: 8116.72 | F18: 12706.976 | G18: 13633.143
C19: R1020 | E19: 6760.5433 | F19: 11716.453 | G19: 9238.4983
C20: R1021 | E20: 7668.1787 | F20: 11518.786 | G20: 8933.3781
C21: R1022 | E21: 10102.027 | F21: 11637.812 | G21: 10650.521
C22: R1023 | D22: 18261.757 | E22: 13457.095 | F22: 12785.637 | G22: 13786.149
C23: R1024 | D23: 32732.187 | E23: 10174.346 | F23: 13360.979 | G23: 12865.149
C24: R1025 | E24: 6886.0368 | F24: 10510.314 | G24: 8788.7823
C25: R1026 | D25: 18709.798 | E25: 11919.608 | F25: 12296.78 | G25: 12489.921
C26: Grand Total | D26: 30129.199 | E26: 11865.269 | F26: 9462.2693 | G26: 13529.918

Sheet Line or Scatter Plot Q1
C3: Age | D3: Average of BMI | E3: Average of HBA1C
C4: 18 | D4: 31.260372 | E4: 5.1409574
C5: 19 | D5: 29.654186 | E5: 5.1781395
C6: 20 | D6: 28.018276 | E6: 9.3244828
C7: 21 | D7: 29.273721 | E7: 5.1174419
C8: 22 | D8: 32.581827 | E8: 5.2767308
C9: 23 | D9: 30.8293 | E9: 5.1892
C10: 24 | D10: 29.0175 | E10: 5.1626087
C11: 25 | D11: 30.344211 | E11: 5.2589474
C12: 26 | D12: 30.441364 | E12: 5.1029545
C13: 27 | D13: 30.316275 | E13: 4.9407843
C14: 28 | D14: 31.029286 | E14: 5.2207143
C15: 29 | D15: 30.763302 | E15: 5.2043396
... C21: 35 | D21: 30.47025 | E21: 5.14525
C22: 36 | D22: 29.481667 | E22: 9.0571429 | G22: Age-Group Averages BMI Correlation | H22: =CORREL(C4:C52,D4:D52) -> 0.27387744
C23: 37 | D23: 30.131538 | E23: 5.2648077
C24: 38 | D24: 28.330568 | E24: 5.2577273
C25: 39 | D25: 30.117 | E25: 5.4913333
C26: 40 | D26: 31.188796 | E26: 5.1522222
C27: 41 | D27: 30.04375 | E27: 9.3903846
C28: 42 | D28: 30.411702 | E28: 5.2017021
C29: 43 | D29: 32.305 | E29: 5.2442
C30: 44 | D30: 30.245 | E30: 9.2566667
C31: 45 | D31: 30.940465 | E31: 5.552093
C32: 46 | D32: 30.956754 | E32: 5.3657895
C33: 47 | D33: 32.274902 | E33: 9.0052941
C34: 48 | D34: 32.017241 | E34: 9.5634483
... C43: 57 | D43: 29.9157 | E43: 9.426
C44: 58 | D44: 31.701279 | E44: 5.3502326 | G44: Age-Group Averages HBA1C Correlation | H44: =CORREL(C4:C51,E4:E51) -> 0.56746982
C45: 59 | D45: 32.402755 | E45: 9.0087755
C46: 60 | D46: 31.349231 | E46: 9.3065385 | G46: Key Findings
C47: 61 | D47: 32.548261 | E47: 8.7708696
C48: 62 | D48: 32.314318 | E48: 9.6813636 | G48: Age and BMI: The correlation of 0.274 indicates a weak positive relationship between age and average BMI.
C49: 63 | D49: 31.893261 | E49: 5.5043478
C50: 64 | D50: 33.284091 | E50: 8.9522727 | G50: Age and HbA1C: The correlation of 0.567 indicates a moderate positive relationship between age and average HbA1C.
C51: 65 | D51: 26.885 | E51: 9.86
C52: Grand Total | D52: 30.972649 | E52: 6.5789979 | G52: Conclusion: In this dataset, average HbA1C shows a stronger positive association with age than average BMI does. These results indicate association, not causation.

Sheet Line or Scatter Plot Q2
C3: Age | D3: Average of charges
C4: 18 | D4: 6611.3116
C5: 19 | D5: 9677.1869
C6: 20 | D6: 7411.4483
C7: 21 | D7: 5214.5293
C8: 22 | D8: 9806.2325
C9: 23 | D9: 11092.934
C10: 24 | D10: 9765.5713
C11: 25 | D11: 9184.887
C12: 26 | D12: 5920.5868
C13: 27 | D13: 11846.242
C14: 28 | D14: 9219.8155
C15: 29 | D15: 9914.8
... C24: 38 | D24: 10223.005
C25: 39 | D25: 13882.344 | G25: Average Charges For Each Age Group Correlation | H25: =CORREL(C4:C52,D4:D52) -> 0.88438568
C26: 40 | D26: 13058.025
C27: 41 | D27: 12031.15
C28: 42 | D28: 13180.462
C29: 43 | D29: 17980.606
C30: 44 | D30: 15162.017
C31: 45 | D31: 15183.109
C32: 46 | D32: 17592.405
C33: 47 | D33: 19264.405
C34: 48 | D34: 15253.752
C35: 49 | D35: 14768.245
C36: 50 | D36: 16208.156
C37: 51 | D37: 17321.896
... C51: 65 | D51: 29330.98
C52: Grand Total | D52: 13529.918

Sheet Dashboard
F8: TOTAL PATIENTS | I8: CANCER HISTORY | L8: AVG. HEALTHCARE CHARGES
F9: 2335 | I9: 391 | L9: =AVERAGE(Healthcare!Q2:Q2336) -> 13529.918
